 * Serving Flask app 'server'
 * Debug mode: on
WARNING: This is a development server. Do not use it in a production deployment. Use a production WSGI server instead.
 * Running on http://127.0.0.1:5000
Press CTRL+C to quit
 * Restarting with stat
 * Debugger is active!
 * Debugger PIN: 652-056-299
Running Query: SELECT * FROM friends;
[<friend.Friend object at 0x105172090>, <friend.Friend object at 0x104e9a210>]
127.0.0.1 - - [02/Aug/2023 15:18:45] "GET / HTTP/1.1" 200 -
127.0.0.1 - - [02/Aug/2023 15:18:45] "GET /favicon.ico HTTP/1.1" 404 -
Running Query: SELECT * FROM friends;
[<friend.Friend object at 0x1079568d0>, <friend.Friend object at 0x107970cd0>]
127.0.0.1 - - [02/Aug/2023 15:22:46] "GET / HTTP/1.1" 200 -
 * Detected change in '/Users/a.steiger/Documents/python/flask_mysql/crud/first_flask/mysqlconnection.py', reloading
 * Restarting with stat
 * Debugger is active!
 * Debugger PIN: 652-056-299
127.0.0.1 - - [02/Aug/2023 15:25:17] "GET / HTTP/1.1" 500 -
Traceback (most recent call last):
  File "/Users/a.steiger/.local/share/virtualenvs/first_flask-FNGkTW3d/lib/python3.11/site-packages/flask/app.py", line 2213, in __call__
    return self.wsgi_app(environ, start_response)
           ^^^^^^^^^^^^^^^^^^^^^^^^^^^^^^^^^^^^^^
  File "/Users/a.steiger/.local/share/virtualenvs/first_flask-FNGkTW3d/lib/python3.11/site-packages/flask/app.py", line 2193, in wsgi_app
    response = self.handle_exception(e)
               ^^^^^^^^^^^^^^^^^^^^^^^^
  File "/Users/a.steiger/.local/share/virtualenvs/first_flask-FNGkTW3d/lib/python3.11/site-packages/flask/app.py", line 2190, in wsgi_app
    response = self.full_dispatch_request()
               ^^^^^^^^^^^^^^^^^^^^^^^^^^^^
  File "/Users/a.steiger/.local/share/virtualenvs/first_flask-FNGkTW3d/lib/python3.11/site-packages/flask/app.py", line 1486, in full_dispatch_request
    rv = self.handle_user_exception(e)
         ^^^^^^^^^^^^^^^^^^^^^^^^^^^^^
  File "/Users/a.steiger/.local/share/virtualenvs/first_flask-FNGkTW3d/lib/python3.11/site-packages/flask/app.py", line 1484, in full_dispatch_request
    rv = self.dispatch_request()
         ^^^^^^^^^^^^^^^^^^^^^^^
  File "/Users/a.steiger/.local/share/virtualenvs/first_flask-FNGkTW3d/lib/python3.11/site-packages/flask/app.py", line 1469, in dispatch_request
    return self.ensure_sync(self.view_functions[rule.endpoint])(**view_args)
           ^^^^^^^^^^^^^^^^^^^^^^^^^^^^^^^^^^^^^^^^^^^^^^^^^^^^^^^^^^^^^^^^^
  File "/Users/a.steiger/Documents/python/flask_mysql/crud/first_flask/server.py", line 8, in index
    friends = Friend.get_all()
              ^^^^^^^^^^^^^^^^
  File "/Users/a.steiger/Documents/python/flask_mysql/crud/first_flask/friend.py", line 17, in get_all
    results = connectToMySQL('first_flask').query_db(query)
              ^^^^^^^^^^^^^^^^^^^^^^^^^^^^^^^^^^^^^^^^^^^^^
  File "/Users/a.steiger/Documents/python/flask_mysql/crud/first_flask/mysqlconnection.py", line 44, in connectToMySQL
    return MySQLConnection(db)
           ^^^^^^^^^^^^^^^^^^^
  File "/Users/a.steiger/Documents/python/flask_mysql/crud/first_flask/mysqlconnection.py", line 7, in __init__
    connection = pymysql.connect(host = 'localhost',
                 ^^^^^^^^^^^^^^^^^^^^^^^^^^^^^^^^^^^
  File "/Users/a.steiger/.local/share/virtualenvs/first_flask-FNGkTW3d/lib/python3.11/site-packages/pymysql/connections.py", line 358, in __init__
    self.connect()
  File "/Users/a.steiger/.local/share/virtualenvs/first_flask-FNGkTW3d/lib/python3.11/site-packages/pymysql/connections.py", line 664, in connect
    self._request_authentication()
  File "/Users/a.steiger/.local/share/virtualenvs/first_flask-FNGkTW3d/lib/python3.11/site-packages/pymysql/connections.py", line 968, in _request_authentication
    auth_packet = self._process_auth(plugin_name, auth_packet)
                  ^^^^^^^^^^^^^^^^^^^^^^^^^^^^^^^^^^^^^^^^^^^^
  File "/Users/a.steiger/.local/share/virtualenvs/first_flask-FNGkTW3d/lib/python3.11/site-packages/pymysql/connections.py", line 1062, in _process_auth
    pkt = self._read_packet()
          ^^^^^^^^^^^^^^^^^^^
  File "/Users/a.steiger/.local/share/virtualenvs/first_flask-FNGkTW3d/lib/python3.11/site-packages/pymysql/connections.py", line 772, in _read_packet
    packet.raise_for_error()
  File "/Users/a.steiger/.local/share/virtualenvs/first_flask-FNGkTW3d/lib/python3.11/site-packages/pymysql/protocol.py", line 221, in raise_for_error
    err.raise_mysql_exception(self._data)
  File "/Users/a.steiger/.local/share/virtualenvs/first_flask-FNGkTW3d/lib/python3.11/site-packages/pymysql/err.py", line 143, in raise_mysql_exception
    raise errorclass(errno, errval)
pymysql.err.OperationalError: (1045, "Access denied for user 'rioot'@'localhost' (using password: YES)")
127.0.0.1 - - [02/Aug/2023 15:25:17] "GET /?__debugger__=yes&cmd=resource&f=style.css HTTP/1.1" 304 -
127.0.0.1 - - [02/Aug/2023 15:25:17] "GET /?__debugger__=yes&cmd=resource&f=debugger.js HTTP/1.1" 304 -
127.0.0.1 - - [02/Aug/2023 15:25:17] "GET /?__debugger__=yes&cmd=resource&f=console.png HTTP/1.1" 304 -
127.0.0.1 - - [02/Aug/2023 15:25:17] "GET /?__debugger__=yes&cmd=resource&f=console.png HTTP/1.1" 304 -
 * Detected change in '/Users/a.steiger/Documents/python/flask_mysql/crud/first_flask/mysqlconnection.py', reloading
 * Restarting with stat
 * Debugger is active!
 * Debugger PIN: 652-056-299
127.0.0.1 - - [02/Aug/2023 15:25:30] "GET / HTTP/1.1" 500 -
Traceback (most recent call last):
  File "/Users/a.steiger/.local/share/virtualenvs/first_flask-FNGkTW3d/lib/python3.11/site-packages/flask/app.py", line 2213, in __call__
    return self.wsgi_app(environ, start_response)
           ^^^^^^^^^^^^^^^^^^^^^^^^^^^^^^^^^^^^^^
  File "/Users/a.steiger/.local/share/virtualenvs/first_flask-FNGkTW3d/lib/python3.11/site-packages/flask/app.py", line 2193, in wsgi_app
    response = self.handle_exception(e)
               ^^^^^^^^^^^^^^^^^^^^^^^^
  File "/Users/a.steiger/.local/share/virtualenvs/first_flask-FNGkTW3d/lib/python3.11/site-packages/flask/app.py", line 2190, in wsgi_app
    response = self.full_dispatch_request()
               ^^^^^^^^^^^^^^^^^^^^^^^^^^^^
  File "/Users/a.steiger/.local/share/virtualenvs/first_flask-FNGkTW3d/lib/python3.11/site-packages/flask/app.py", line 1486, in full_dispatch_request
    rv = self.handle_user_exception(e)
         ^^^^^^^^^^^^^^^^^^^^^^^^^^^^^
  File "/Users/a.steiger/.local/share/virtualenvs/first_flask-FNGkTW3d/lib/python3.11/site-packages/flask/app.py", line 1484, in full_dispatch_request
    rv = self.dispatch_request()
         ^^^^^^^^^^^^^^^^^^^^^^^
  File "/Users/a.steiger/.local/share/virtualenvs/first_flask-FNGkTW3d/lib/python3.11/site-packages/flask/app.py", line 1469, in dispatch_request
    return self.ensure_sync(self.view_functions[rule.endpoint])(**view_args)
           ^^^^^^^^^^^^^^^^^^^^^^^^^^^^^^^^^^^^^^^^^^^^^^^^^^^^^^^^^^^^^^^^^
  File "/Users/a.steiger/Documents/python/flask_mysql/crud/first_flask/server.py", line 8, in index
    friends = Friend.get_all()
              ^^^^^^^^^^^^^^^^
  File "/Users/a.steiger/Documents/python/flask_mysql/crud/first_flask/friend.py", line 17, in get_all
    results = connectToMySQL('first_flask').query_db(query)
              ^^^^^^^^^^^^^^^^^^^^^^^^^^^^^^^^^^^^^^^^^^^^^
  File "/Users/a.steiger/Documents/python/flask_mysql/crud/first_flask/mysqlconnection.py", line 44, in connectToMySQL
    return MySQLConnection(db)
           ^^^^^^^^^^^^^^^^^^^
  File "/Users/a.steiger/Documents/python/flask_mysql/crud/first_flask/mysqlconnection.py", line 7, in __init__
    connection = pymysql.connect(host = 'localhost',
                 ^^^^^^^^^^^^^^^^^^^^^^^^^^^^^^^^^^^
  File "/Users/a.steiger/.local/share/virtualenvs/first_flask-FNGkTW3d/lib/python3.11/site-packages/pymysql/connections.py", line 316, in __init__
    self.encoding = charset_by_name(self.charset).encoding
                    ^^^^^^^^^^^^^^^^^^^^^^^^^^^^^^^^^^^^^^
AttributeError: 'NoneType' object has no attribute 'encoding'
127.0.0.1 - - [02/Aug/2023 15:25:30] "GET /?__debugger__=yes&cmd=resource&f=style.css HTTP/1.1" 304 -
127.0.0.1 - - [02/Aug/2023 15:25:30] "GET /?__debugger__=yes&cmd=resource&f=debugger.js HTTP/1.1" 304 -
127.0.0.1 - - [02/Aug/2023 15:25:30] "GET /?__debugger__=yes&cmd=resource&f=console.png HTTP/1.1" 304 -
127.0.0.1 - - [02/Aug/2023 15:25:30] "GET /?__debugger__=yes&cmd=resource&f=console.png HTTP/1.1" 304 -
 * Detected change in '/Users/a.steiger/Documents/python/flask_mysql/crud/first_flask/mysqlconnection.py', reloading
 * Restarting with stat
 * Debugger is active!
 * Debugger PIN: 652-056-299
Running Query: SELECT * FROM friends;
[<friend.Friend object at 0x102789bd0>, <friend.Friend object at 0x102788750>]
127.0.0.1 - - [02/Aug/2023 15:25:38] "GET / HTTP/1.1" 200 -
 * Detected change in '/Users/a.steiger/Documents/python/flask_mysql/crud/first_flask/mysqlconnection.py', reloading
 * Restarting with stat
 * Debugger is active!
 * Debugger PIN: 652-056-299
Running Query: SELECT * FROM friends;
[<friend.Friend object at 0x102e30710>, <friend.Friend object at 0x104d57f10>]
127.0.0.1 - - [02/Aug/2023 15:25:51] "GET / HTTP/1.1" 200 -
Running Query: SELECT * FROM friends;
[<friend.Friend object at 0x104d5f310>, <friend.Friend object at 0x104d5fe90>]
127.0.0.1 - - [02/Aug/2023 15:25:52] "GET / HTTP/1.1" 200 -
 * Detected change in '/Users/a.steiger/Documents/python/flask_mysql/crud/first_flask/mysqlconnection.py', reloading
 * Restarting with stat
 * Debugger is active!
 * Debugger PIN: 652-056-299
 * Detected change in '/Users/a.steiger/Documents/python/flask_mysql/crud/first_flask/mysqlconnection.py', reloading
 * Restarting with stat
 * Debugger is active!
 * Debugger PIN: 652-056-299
127.0.0.1 - - [02/Aug/2023 15:26:06] "GET / HTTP/1.1" 500 -
Traceback (most recent call last):
  File "/Users/a.steiger/.local/share/virtualenvs/first_flask-FNGkTW3d/lib/python3.11/site-packages/flask/app.py", line 2213, in __call__
    return self.wsgi_app(environ, start_response)
           ^^^^^^^^^^^^^^^^^^^^^^^^^^^^^^^^^^^^^^
  File "/Users/a.steiger/.local/share/virtualenvs/first_flask-FNGkTW3d/lib/python3.11/site-packages/flask/app.py", line 2193, in wsgi_app
    response = self.handle_exception(e)
               ^^^^^^^^^^^^^^^^^^^^^^^^
  File "/Users/a.steiger/.local/share/virtualenvs/first_flask-FNGkTW3d/lib/python3.11/site-packages/flask/app.py", line 2190, in wsgi_app
    response = self.full_dispatch_request()
               ^^^^^^^^^^^^^^^^^^^^^^^^^^^^
  File "/Users/a.steiger/.local/share/virtualenvs/first_flask-FNGkTW3d/lib/python3.11/site-packages/flask/app.py", line 1486, in full_dispatch_request
    rv = self.handle_user_exception(e)
         ^^^^^^^^^^^^^^^^^^^^^^^^^^^^^
  File "/Users/a.steiger/.local/share/virtualenvs/first_flask-FNGkTW3d/lib/python3.11/site-packages/flask/app.py", line 1484, in full_dispatch_request
    rv = self.dispatch_request()
         ^^^^^^^^^^^^^^^^^^^^^^^
  File "/Users/a.steiger/.local/share/virtualenvs/first_flask-FNGkTW3d/lib/python3.11/site-packages/flask/app.py", line 1469, in dispatch_request
    return self.ensure_sync(self.view_functions[rule.endpoint])(**view_args)
           ^^^^^^^^^^^^^^^^^^^^^^^^^^^^^^^^^^^^^^^^^^^^^^^^^^^^^^^^^^^^^^^^^
  File "/Users/a.steiger/Documents/python/flask_mysql/crud/first_flask/server.py", line 8, in index
    friends = Friend.get_all()
              ^^^^^^^^^^^^^^^^
  File "/Users/a.steiger/Documents/python/flask_mysql/crud/first_flask/friend.py", line 17, in get_all
    results = connectToMySQL('first_flask').query_db(query)
              ^^^^^^^^^^^^^^^^^^^^^^^^^^^^^^^^^^^^^^^^^^^^^
  File "/Users/a.steiger/Documents/python/flask_mysql/crud/first_flask/mysqlconnection.py", line 44, in connectToMySQL
    return MySQLConnection(db)
           ^^^^^^^^^^^^^^^^^^^
  File "/Users/a.steiger/Documents/python/flask_mysql/crud/first_flask/mysqlconnection.py", line 12, in __init__
    cursorclass = pymysql.cursors.DictCursors,
                  ^^^^^^^^^^^^^^^^^^^^^^^^^^^^
AttributeError: module 'pymysql.cursors' has no attribute 'DictCursors'
127.0.0.1 - - [02/Aug/2023 15:26:06] "GET /?__debugger__=yes&cmd=resource&f=style.css HTTP/1.1" 304 -
127.0.0.1 - - [02/Aug/2023 15:26:06] "GET /?__debugger__=yes&cmd=resource&f=debugger.js HTTP/1.1" 304 -
127.0.0.1 - - [02/Aug/2023 15:26:06] "GET /?__debugger__=yes&cmd=resource&f=console.png HTTP/1.1" 304 -
127.0.0.1 - - [02/Aug/2023 15:26:06] "GET /?__debugger__=yes&cmd=resource&f=console.png HTTP/1.1" 304 -
 * Detected change in '/Users/a.steiger/Documents/python/flask_mysql/crud/first_flask/mysqlconnection.py', reloading
 * Restarting with stat
 * Debugger is active!
 * Debugger PIN: 652-056-299
 * Detected change in '/Users/a.steiger/Documents/python/flask_mysql/crud/first_flask/mysqlconnection.py', reloading
 * Restarting with stat
 * Debugger is active!
 * Debugger PIN: 652-056-299
127.0.0.1 - - [02/Aug/2023 15:26:37] "GET / HTTP/1.1" 500 -
Traceback (most recent call last):
  File "/Users/a.steiger/.local/share/virtualenvs/first_flask-FNGkTW3d/lib/python3.11/site-packages/flask/app.py", line 2213, in __call__
    return self.wsgi_app(environ, start_response)
           ^^^^^^^^^^^^^^^^^^^^^^^^^^^^^^^^^^^^^^
  File "/Users/a.steiger/.local/share/virtualenvs/first_flask-FNGkTW3d/lib/python3.11/site-packages/flask/app.py", line 2193, in wsgi_app
    response = self.handle_exception(e)
               ^^^^^^^^^^^^^^^^^^^^^^^^
  File "/Users/a.steiger/.local/share/virtualenvs/first_flask-FNGkTW3d/lib/python3.11/site-packages/flask/app.py", line 2190, in wsgi_app
    response = self.full_dispatch_request()
               ^^^^^^^^^^^^^^^^^^^^^^^^^^^^
  File "/Users/a.steiger/.local/share/virtualenvs/first_flask-FNGkTW3d/lib/python3.11/site-packages/flask/app.py", line 1486, in full_dispatch_request
    rv = self.handle_user_exception(e)
         ^^^^^^^^^^^^^^^^^^^^^^^^^^^^^
  File "/Users/a.steiger/.local/share/virtualenvs/first_flask-FNGkTW3d/lib/python3.11/site-packages/flask/app.py", line 1484, in full_dispatch_request
    rv = self.dispatch_request()
         ^^^^^^^^^^^^^^^^^^^^^^^
  File "/Users/a.steiger/.local/share/virtualenvs/first_flask-FNGkTW3d/lib/python3.11/site-packages/flask/app.py", line 1469, in dispatch_request
    return self.ensure_sync(self.view_functions[rule.endpoint])(**view_args)
           ^^^^^^^^^^^^^^^^^^^^^^^^^^^^^^^^^^^^^^^^^^^^^^^^^^^^^^^^^^^^^^^^^
  File "/Users/a.steiger/Documents/python/flask_mysql/crud/first_flask/server.py", line 8, in index
    friends = Friend.get_all()
              ^^^^^^^^^^^^^^^^
  File "/Users/a.steiger/Documents/python/flask_mysql/crud/first_flask/friend.py", line 17, in get_all
    results = connectToMySQL('first_flask').query_db(query)
              ^^^^^^^^^^^^^^^^^^^^^^^^^^^^^^^^^^^^^^^^^^^^^
  File "/Users/a.steiger/Documents/python/flask_mysql/crud/first_flask/mysqlconnection.py", line 44, in connectToMySQL
    return MySQLConnection(db)
           ^^^^^^^^^^^^^^^^^^^
  File "/Users/a.steiger/Documents/python/flask_mysql/crud/first_flask/mysqlconnection.py", line 10, in __init__
    db = db,
         ^^^
NameError: name 'db' is not defined
127.0.0.1 - - [02/Aug/2023 15:26:37] "GET /?__debugger__=yes&cmd=resource&f=debugger.js HTTP/1.1" 304 -
127.0.0.1 - - [02/Aug/2023 15:26:37] "GET /?__debugger__=yes&cmd=resource&f=style.css HTTP/1.1" 304 -
127.0.0.1 - - [02/Aug/2023 15:26:37] "GET /?__debugger__=yes&cmd=resource&f=console.png HTTP/1.1" 304 -
127.0.0.1 - - [02/Aug/2023 15:26:37] "GET /?__debugger__=yes&cmd=resource&f=console.png HTTP/1.1" 304 -
 * Detected change in '/Users/a.steiger/Documents/python/flask_mysql/crud/first_flask/mysqlconnection.py', reloading
 * Restarting with stat
 * Debugger is active!
 * Debugger PIN: 652-056-299
 * Detected change in '/Users/a.steiger/Documents/python/flask_mysql/crud/first_flask/mysqlconnection.py', reloading
 * Restarting with stat
 * Debugger is active!
 * Debugger PIN: 652-056-299
127.0.0.1 - - [02/Aug/2023 15:26:58] "GET / HTTP/1.1" 500 -
Traceback (most recent call last):
  File "/Users/a.steiger/.local/share/virtualenvs/first_flask-FNGkTW3d/lib/python3.11/site-packages/pymysql/connections.py", line 644, in connect
    sock = socket.create_connection(
           ^^^^^^^^^^^^^^^^^^^^^^^^^
  File "/Library/Frameworks/Python.framework/Versions/3.11/lib/python3.11/socket.py", line 827, in create_connection
    for res in getaddrinfo(host, port, 0, SOCK_STREAM):
               ^^^^^^^^^^^^^^^^^^^^^^^^^^^^^^^^^^^^^^^^
  File "/Library/Frameworks/Python.framework/Versions/3.11/lib/python3.11/socket.py", line 962, in getaddrinfo
    for res in _socket.getaddrinfo(host, port, family, type, proto, flags):
               ^^^^^^^^^^^^^^^^^^^^^^^^^^^^^^^^^^^^^^^^^^^^^^^^^^^^^^^^^^^^
socket.gaierror: [Errno 8] nodename nor servname provided, or not known

During handling of the above exception, another exception occurred:

Traceback (most recent call last):
  File "/Users/a.steiger/.local/share/virtualenvs/first_flask-FNGkTW3d/lib/python3.11/site-packages/flask/app.py", line 2213, in __call__
    return self.wsgi_app(environ, start_response)
           ^^^^^^^^^^^^^^^^^^^^^^^^^^^^^^^^^^^^^^
  File "/Users/a.steiger/.local/share/virtualenvs/first_flask-FNGkTW3d/lib/python3.11/site-packages/flask/app.py", line 2193, in wsgi_app
    response = self.handle_exception(e)
               ^^^^^^^^^^^^^^^^^^^^^^^^
  File "/Users/a.steiger/.local/share/virtualenvs/first_flask-FNGkTW3d/lib/python3.11/site-packages/flask/app.py", line 2190, in wsgi_app
    response = self.full_dispatch_request()
               ^^^^^^^^^^^^^^^^^^^^^^^^^^^^
  File "/Users/a.steiger/.local/share/virtualenvs/first_flask-FNGkTW3d/lib/python3.11/site-packages/flask/app.py", line 1486, in full_dispatch_request
    rv = self.handle_user_exception(e)
         ^^^^^^^^^^^^^^^^^^^^^^^^^^^^^
  File "/Users/a.steiger/.local/share/virtualenvs/first_flask-FNGkTW3d/lib/python3.11/site-packages/flask/app.py", line 1484, in full_dispatch_request
    rv = self.dispatch_request()
         ^^^^^^^^^^^^^^^^^^^^^^^
  File "/Users/a.steiger/.local/share/virtualenvs/first_flask-FNGkTW3d/lib/python3.11/site-packages/flask/app.py", line 1469, in dispatch_request
    return self.ensure_sync(self.view_functions[rule.endpoint])(**view_args)
           ^^^^^^^^^^^^^^^^^^^^^^^^^^^^^^^^^^^^^^^^^^^^^^^^^^^^^^^^^^^^^^^^^
  File "/Users/a.steiger/Documents/python/flask_mysql/crud/first_flask/server.py", line 8, in index
    friends = Friend.get_all()
              ^^^^^^^^^^^^^^^^
  File "/Users/a.steiger/Documents/python/flask_mysql/crud/first_flask/friend.py", line 17, in get_all
    results = connectToMySQL('first_flask').query_db(query)
              ^^^^^^^^^^^^^^^^^^^^^^^^^^^^^^^^^^^^^^^^^^^^^
  File "/Users/a.steiger/Documents/python/flask_mysql/crud/first_flask/mysqlconnection.py", line 44, in connectToMySQL
    return MySQLConnection(db)
           ^^^^^^^^^^^^^^^^^^^
  File "/Users/a.steiger/Documents/python/flask_mysql/crud/first_flask/mysqlconnection.py", line 7, in __init__
    connection = pymysql.connect(host = 'locealhost',
                 ^^^^^^^^^^^^^^^^^^^^^^^^^^^^^^^^^^^^
  File "/Users/a.steiger/.local/share/virtualenvs/first_flask-FNGkTW3d/lib/python3.11/site-packages/pymysql/connections.py", line 358, in __init__
    self.connect()
  File "/Users/a.steiger/.local/share/virtualenvs/first_flask-FNGkTW3d/lib/python3.11/site-packages/pymysql/connections.py", line 711, in connect
    raise exc
pymysql.err.OperationalError: (2003, "Can't connect to MySQL server on 'locealhost' ([Errno 8] nodename nor servname provided, or not known)")